Workbook

Sheet Сводка
A1: AIMAX — Финансовый план под раунд инвестиций 200 000 €
A2: Период плана: июнь 2026 — май 2027 (12 месяцев). Базовые данные по факту на 30.04.2026.
A4: 1. ТЕКУЩЕЕ СОСТОЯНИЕ AIMAX (по факту на 30.04.2026)
A5: Период наблюдения | B5: 8 месяцев фактических данных | C5: Сентябрь 2025 — Апрель 2026
A6: Клиентов с контрактом | B6: 20 | C6: Активная клиентская база
A7: Сумма всех контрактов (booked) | B7: 101451 | C7: € — закрытые контракты, в работе и завершённые
A8: Оплачено (cash in) | B8: 71975 | C8: € — фактические поступления
A9: Неоплаченный остаток по контрактам | B9: 29476 | C9: € — законтрактованная будущая выручка
A10: Средняя месячная выручка (последние 4 мес.) | B10: 9510 | C10: € — стабилизация на уровне €10K/мес
A11: Операционная маржа (последние 6 месяцев) | B11: Положительная | C11: Чистая прибыль 6 месяцев из 7 (с ноября 2025)
A12: География клиентов | B12: Россия, Сербия, Германия, ОАЭ, Тайланд | C12: 5 стран
A13: Recurring клиентов (с регулярными платежами) | B13: 3 | C13: Esnad, Payde, NeuroPublisher
A14: MRR (Monthly Recurring Revenue) | B14: 7700 | C14: € — текущий уровень (эквивалент $8 396)
A15: Партнёрская сеть | B15: 7 активных партнёров | C15: Agama, Maximum, Дмитрий Л., Елена Л. и др.
A16: Команда (full-time + part-time) | B16: 6 | C16: Основатели и сотрудники
A18: 2. СТРУКТУРА ВХОДА ИНВЕСТОРА
A19: Юридическая структура (международный трек) | B19: C-Corp (штат Делавэр, США) | C19: Венчурный стандарт
A20: Сербская операционная компания | B20: DOO MAYMAKS | C20: Сохраняется как OpCo под HoldCo
A21: Технологический актив | B21: AIMAX | C21: Передаётся в C-Corp до closing
A22: Тип входа в C-Corp | B22: Физическое, юридическое или иное лицо | C22: По выбору инвестора
A23: Сумма инвестиции | B23: 200000 | C23: €
A24: Доля инвестора в C-Corp | B24: 0.05 | C24: 5%
A25: Pre-money оценка компании | B25: 3800000 | C25: €
A26: Post-money оценка компании | B26: 4000000 | C26: €
A27: Российский трек (отдельная компания) | B27: 50/50 распределение прибыли | C27: Светлана контролирует операционно
A28: Vesting основателей | B28: 3 года с 1-year cliff | C28: Стандарт венчурного раунда
A30: 3. РАСПРЕДЕЛЕНИЕ 200 000 € ПО НАПРАВЛЕНИЯМ
A31: Направление | B31: Сумма | C31: Доля | D31: Комментарий
A32: Маркетинг ЕС и США | B32: 100000 | C32: =B32/B36 -> 0.5 | D32: Контент, SEO, платная реклама, PR, конференции, работа с РБК
A33: Расширение команды | B33: 60000 | C33: =B33/B36 -> 0.3 | D33: Sales EU, 2 разработчика, поддержка клиентов
A34: Технологическое усиление продукта | B34: 25000 | C34: =B34/B36 -> 0.125 | D34: Мультиязычность, GDPR, AI-инфраструктура, SOC 2 prep
A35: Юридическое оформление структуры | B35: 15000 | C35: =B35/B36 -> 0.075 | D35: C-Corp Делавэр, передача IP, договоры, ТМ EU+US
A36: ИТОГО | B36: =SUM(B32:B35) -> 200000 | C36: =SUM(C32:C35) -> 1
A38: 4. ПРОГНОЗ КЛЮЧЕВЫХ ПОКАЗАТЕЛЕЙ (12 месяцев)
A39: Точка операционной безубыточности AIMAX | B39: Декабрь 2026 — Январь 2027 | C39: Расходы покрываются выручкой
A40: Прогноз выручки AIMAX за 12 мес. (без РФ-трека) | B40: ='Cash Flow'!N5 -> 511000 | C40: € — международная компания
A41: Прогноз операционных расходов AIMAX за 12 мес. | B41: ='Cash Flow'!N11 -> 474500 | C41: С учётом расширения команды и маркетинга
A42: Прогнозируемая чистая операционная прибыль | B42: ='Cash Flow'!N12 -> 36500 | C42: Совокупно за период
A43: Денежный остаток на конец периода (май 2027) | B43: ='Cash Flow'!M17 -> 236500 | C43: Запас для следующего раунда
A44: Прогнозируемый MRR на май 2027 | B44: 22000 | C44: € — рост в 2.9x от текущих €7 700
...

Sheet Cash Flow
A1: AIMAX (международная компания) — Помесячный план движения денежных средств
A2: Базовая точка: на 30.04.2026 — выручка ~€10K/мес, MRR €7 700, 20 клиентов. Российский трек учитывается на отдельном листе «РФ Трек».
A3: Показатель / Месяц | B3: Июнь-26 | C3: Июль-26 | D3: Авг-26 | E3: Сен-26 | F3: Окт-26 | G3: Ноя-26 | H3: Дек-26 | I3: Янв-27 | J3: Фев-27 | K3: Мар-27 | L3: Апр-27 | M3: Май-27 | N3: ИТОГО
A4: ДОХОДЫ AIMAX
A5: Выручка AIMAX (международная) | B5: 12000 | C5: 15000 | D5: 18000 | E5: 24000 | F5: 31000 | G5: 38000 | H5: 46000 | I5: 52000 | J5: 58000 | K5: 65000 | L5: 72000 | M5: 80000 | N5: =SUM(B5:M5) -> 511000
A6: ОПЕРАЦИОННЫЕ РАСХОДЫ AIMAX
A7: Фонд оплаты труда | B7: 7000 | C7: 10000 | D7: 11000 | E7: 18000 | F7: 21000 | G7: 21500 | H7: 21500 | I7: 25000 | J7: 25000 | K7: 26000 | L7: 27000 | M7: 28000 | N7: =SUM(B7:M7) -> 241000
A8: Маркетинг и продвижение | B8: 2000 | C8: 5000 | D8: 8000 | E8: 18000 | F8: 20000 | G8: 18000 | H8: 16000 | I8: 15000 | J8: 14000 | K8: 13000 | L8: 12000 | M8: 12000 | N8: =SUM(B8:M8) -> 153000
A9: Технологии, инфраструктура, серверы | B9: 4000 | C9: 5000 | D9: 5000 | E9: 5000 | F9: 4000 | G9: 3500 | H9: 3000 | I9: 3000 | J9: 3000 | K9: 3000 | L9: 3000 | M9: 3000 | N9: =SUM(B9:M9) -> 44500
A10: Аренда, налоги, юр.расходы | B10: 8000 | C10: 3000 | D10: 2000 | E10: 3000 | F10: 2500 | G10: 2500 | H10: 2500 | I10: 2500 | J10: 2500 | K10: 2500 | L10: 2500 | M10: 2500 | N10: =SUM(B10:M10) -> 36000
A11: ИТОГО операционные расходы | B11: =SUM(B7:B10) -> 21000 | C11: =SUM(C7:C10) -> 23000 | D11: =SUM(D7:D10) -> 26000 | E11: =SUM(E7:E10) -> 44000 | F11: =SUM(F7:F10) -> 47500 | G11: =SUM(G7:G10) -> 45500 | H11: =SUM(H7:H10) -> 43000 | I11: =SUM(I7:I10) -> 45500 | ... N11: =SUM(N7:N10) -> 474500
A12: Операционный денежный поток | B12: =B5-B11 -> -9000 | C12: =C5-C11 -> -8000 | D12: =D5-D11 -> -8000 | E12: =E5-E11 -> -20000 | F12: =F5-F11 -> -16500 | G12: =G5-G11 -> -7500 | H12: =H5-H11 -> 3000 | I12: =I5-I11 -> 6500 | ... M12: =M5-M11 -> 34500 | N12: =SUM(B12:M12) -> 36500
A14: ИНВЕСТИЦИИ И ОСТАТОК НА СЧЁТЕ
A15: Поступление инвестиций (транши) | B15: 20000 | C15: 10000 | D15: 5000 | E15: 65000 | F15: 50000 | G15: 30000 | H15: 20000 | I15: 0 | J15: 0 | K15: 0 | L15: 0 | M15: 0 | N15: =SUM(B15:M15) -> 200000
A16: Чистый денежный поток за месяц | B16: =B12+B15 -> 11000 | C16: =C12+C15 -> 2000 | D16: =D12+D15 -> -3000 | E16: =E12+E15 -> 45000 | F16: =F12+F15 -> 33500 | G16: =G12+G15 -> 22500 | H16: =H12+H15 -> 23000 | I16: =I12+I15 -> 6500 | ... M16: =M12+M15 -> 34500
A17: Накопленный остаток на счёте | B17: =B16 -> 11000 | C17: =B17+C16 -> 13000 | D17: =C17+D16 -> 10000 | E17: =D17+E16 -> 55000 | F17: =E17+F16 -> 88500 | G17: =F17+G16 -> 111000 | H17: =G17+H16 -> 134000 | I17: =H17+I16 -> 140500 | J17: =I17+J16 -> 154000 | ... M17: =L17+M16 -> 236500
A19: Точка операционной безубыточности AIMAX: декабрь 2026 — январь 2027. Сумма инвестиций распределяется траншами: 20K летом (структурные расходы), 170K — основная фаза с сентября.

Sheet РФ Трек
A1: РФ ТРЕК — Помесячный план новой российской компании (50/50)
A2: Светлана: фронт-офис Москва (директор, финансы, бухгалтерия, продажи). AIMAX: бэк-офис Сербия (техническая часть, исполнение заказов). Распределение 50/50 от чистого дохода компании.
A3: Показатель / Месяц | B3: Июнь-26 | C3: Июль-26 | D3: Авг-26 | E3: Сен-26 | F3: Окт-26 | G3: Ноя-26 | H3: Дек-26 | I3: Янв-27 | J3: Фев-27 | K3: Мар-27 | L3: Апр-27 | M3: Май-27 | N3: ИТОГО
A4: ВЫРУЧКА РФ-КОМПАНИИ
A5: Поступления от клиентов | B5: 0 | C5: 0 | D5: 0 | E5: 5000 | F5: 8000 | G5: 11000 | H5: 14000 | I5: 17000 | J5: 20000 | K5: 23000 | L5: 26000 | M5: 30000 | N5: =SUM(B5:M5) -> 154000
A6: НАЛОГИ
A7: УСН 6% (упрощённая, на доходы) | B7: =B5*0.06 -> 0 | C7: =C5*0.06 -> 0 | D7: =D5*0.06 -> 0 | E7: =E5*0.06 -> 300 | F7: =F5*0.06 -> 480 | G7: =G5*0.06 -> 660 | H7: =H5*0.06 -> 840 | I7: =I5*0.06 -> 1020 | ... M7: =M5*0.06 -> 1800 | N7: =SUM(B7:M7) -> 9240
A8: Чистый доход после налогов | B8: =B5-B7 -> 0 | C8: =C5-C7 -> 0 | D8: =D5-D7 -> 0 | E8: =E5-E7 -> 4700 | F8: =F5-F7 -> 7520 | G8: =G5-G7 -> 10340 | H8: =H5-H7 -> 13160 | I8: =I5-I7 -> 15980 | ... M8: =M5-M7 -> 28200 | N8: =SUM(B8:M8) -> 144760
A9: РАСПРЕДЕЛЕНИЕ 50/50
A10: Доля инвестора (50%) — фронт-офис Москва | B10: =B8*0.5 -> 0 | C10: =C8*0.5 -> 0 | D10: =D8*0.5 -> 0 | E10: =E8*0.5 -> 2350 | F10: =F8*0.5 -> 3760 | G10: =G8*0.5 -> 5170 | H10: =H8*0.5 -> 6580 | I10: =I8*0.5 -> 7990 | ... M10: =M8*0.5 -> 14100 | N10: =SUM(B10:M10) -> 72380
A11: Доля AIMAX (50%) — бэк-офис Сербия | B11: =B8*0.5 -> 0 | C11: =C8*0.5 -> 0 | D11: =D8*0.5 -> 0 | E11: =E8*0.5 -> 2350 | F11: =F8*0.5 -> 3760 | G11: =G8*0.5 -> 5170 | H11: =H8*0.5 -> 6580 | I11: =I8*0.5 -> 7990 | ... M11: =M8*0.5 -> 14100 | N11: =SUM(B11:M11) -> 72380
A12: Накопленный возврат инвестору | B12: =B10 -> 0 | C12: =B12+C10 -> 0 | D12: =C12+D10 -> 0 | E12: =D12+E10 -> 2350 | F12: =E12+F10 -> 6110 | G12: =F12+G10 -> 11280 | H12: =G12+H10 -> 17860 | I12: =H12+I10 -> 25850 | J12: =I12+J10 -> 35250 | ... M12: =L12+M10 -> 72380
A14: Модель: РФ-компания работает по упрощённой системе налогообложения (УСН 6% на доходы). Технические расходы (исполнение заказов) покрываются AIMAX из своей 50% доли. Операционные расходы фронт-офиса (Москва) покрываются Светланой из её 50% доли.
A16: Ключевые цифры для инвестора: первый месяц с выручкой (сентябрь 2026) — 2 350 € доли. К маю 2027 — 14 100 € ежемесячно. Совокупный возврат за 9 месяцев работы — около 72 380 €.

Sheet Распределение 200K
A1: Детальное распределение инвестиций 200 000 € по направлениям
A3: Направление | B3: Подкатегория | C3: Сумма | D3: Срок реализации | E3: Комментарий
A4: Маркетинг ЕС/США | B4: Контент-маркетинг и SEO (специалист, статьи, креативы) | C4: 30000 | D4: Июль 2026 — Май 2027 | E4: Постоянный поток контента для входа в ЕС
A5: Маркетинг ЕС/США | B5: Платная реклама (Google Ads, LinkedIn, контекст) | C5: 30000 | D5: Сентябрь 2026 — Апрель 2027 | E5: Активная фаза привлечения B2B-лидов
A6: Маркетинг ЕС/США | B6: Конференции и нетворкинг (Web Summit, GITEX и т.п.) | C6: 30000 | D6: Октябрь 2026 — Май 2027 | E6: Прямые контакты с MENA/EU
A7: Маркетинг ЕС/США | B7: PR и медиа | C7: 10000 | D7: Сентябрь 2026 — Май 2027 | E7: Медиа-присутствие и репутационный след
A8: Расширение команды | B8: Sales-менеджер EU | C8: 16000 | D8: Сентябрь — Декабрь 2026 | E8: Bilingual EN/DE/ES, B2B-опыт
A9: Расширение команды | B9: 2 разработчика для масштабирования delivery | C9: 36000 | D9: Июль — Декабрь 2026 | E9: Middle-разработчики, снятие bottleneck
A10: Расширение команды | B10: Поддержка клиентов и аккаунт-менеджмент | C10: 8000 | D10: Октябрь 2026 — Май 2027 | E10: Onboarding и удержание (защита от churn)
A11: Технологическое усиление | B11: Доработка под международные стандарты | C11: 12000 | D11: Июнь — Сентябрь 2026 | E11: Локализация, GDPR, мультивалютность
A12: Технологическое усиление | B12: AI-инфраструктура (API, токены, инференс) | C12: 8000 | D12: Июль 2026 — Май 2027 | E12: Доступ к OpenAI/Anthropic/Google API
A13: Технологическое усиление | B13: SOC 2 readiness и compliance prep | C13: 5000 | D13: Август — Декабрь 2026 | E13: Подготовка к корпоративным клиентам ЕС
A14: Юридическое оформление | B14: Регистрация C-Corp Делавэр + EIN + банковский счёт | C14: 5000 | D14: Июнь — Июль 2026 | E14: Stripe Atlas или прямой агент
A15: Юридическое оформление | B15: Передача технологического актива в C-Corp | C15: 5000 | D15: Июнь — Август 2026 | E15: Закрытие критического вопроса перед раундом
... A18: Юридическое оформление | B18: Прочее (нотариус, апостили, переводы) | C18: 2000 | D18: Постоянно | E18: Резерв на юридические работы
A19: ИТОГО | C19: =SUM(C4:C18) -> 200000

Sheet Прогноз роста
A1: AIMAX (международная) — Прогноз роста выручки и клиентской базы
A2: Базовая точка (30.04.2026): MRR €7 700, ARPA €550, 20 клиентов. Прогноз — рост международной компании без учёта РФ-трека (он на отдельном листе).
A3: Показатель / Месяц | B3: Июнь-26 | C3: Июль-26 | D3: Авг-26 | E3: Сен-26 | F3: Окт-26 | G3: Ноя-26 | H3: Дек-26 | I3: Янв-27 | J3: Фев-27 | K3: Мар-27 | L3: Апр-27 | M3: Май-27 | N3: ИТОГО
A4: ИСТОЧНИКИ ВЫРУЧКИ AIMAX (€)
A5: MRR (Monthly Recurring Revenue) | B5: 8000 | C5: 8500 | D5: 9000 | E5: 10500 | F5: 12000 | G5: 13500 | H5: 15000 | I5: 16500 | J5: 18000 | K5: 19500 | L5: 21000 | M5: 22000
A6: Setup-проекты (ЕС, MENA, разовые) | B6: 3000 | C6: 5000 | D6: 7000 | E6: 10500 | F6: 14500 | G6: 19000 | H6: 24000 | I6: 28000 | J6: 32000 | K6: 36500 | L6: 41000 | M6: 47000
A7: Партнёрский канал (Agama, Maximum и новые) | B7: 1000 | C7: 1500 | D7: 2000 | E7: 3000 | F7: 4500 | G7: 5500 | H7: 7000 | I7: 7500 | J7: 8000 | K7: 9000 | L7: 10000 | M7: 11000
A8: ИТОГО выручка AIMAX | B8: =SUM(B5:B7) -> 12000 | C8: =SUM(C5:C7) -> 15000 | D8: =SUM(D5:D7) -> 18000 | E8: =SUM(E5:E7) -> 24000 | F8: =SUM(F5:F7) -> 31000 | G8: =SUM(G5:G7) -> 38000 | H8: =SUM(H5:H7) -> 46000 | I8: =SUM(I5:I7) -> 52000 | ... M8: =SUM(M5:M7) -> 80000 | N8: =SUM(B8:M8) -> 511000
A9: Доля Recurring в выручке (%) | B9: =B5/B8 -> 0.66666667 | C9: =C5/C8 -> 0.56666667 | D9: =D5/D8 -> 0.5 | E9: =E5/E8 -> 0.4375 | F9: =F5/F8 -> 0.38709677 | G9: =G5/G8 -> 0.35526316 | H9: =H5/H8 -> 0.32608696 | I9: =I5/I8 -> 0.31730769 | ... M9: =M5/M8 -> 0.275
A11: КЛИЕНТСКАЯ БАЗА
A12: Активные клиенты (нарастающим итогом) | B12: 21 | C12: 23 | D12: 25 | E12: 28 | F12: 32 | G12: 36 | H12: 40 | I12: 42 | J12: 44 | K12: 45 | L12: 47 | M12: 48
A13: Из них recurring клиенты | B13: 4 | C13: 5 | D13: 6 | E13: 7 | F13: 9 | G13: 11 | H13: 13 | I13: 15 | J13: 17 | K13: 19 | L13: 21 | M13: 23
A14: Новые клиенты (за месяц) | B14: 1 | C14: 2 | D14: 2 | E14: 3 | F14: 4 | G14: 4 | H14: 4 | I14: 2 | J14: 2 | K14: 1 | L14: 2 | M14: 1
A15: ARPC (средняя выручка на клиента) | B15: =B8/B12 -> 571.42857 | C15: =C8/C12 -> 652.17391 | D15: =D8/D12 -> 720 | E15: =E8/E12 -> 857.14286 | F15: =F8/F12 -> 968.75 | G15: =G8/G12 -> 1055.5556 | H15: =H8/H12 -> 1150 | I15: =I8/I12 -> 1238.0952 | ... M15: =M8/M12 -> 1666.6667
